<robot name="robot_arm">
 	<link name="base_link">
		<visual>
		    <origin xyz="0 0 0.061" rpy="0 0 0"/>
			<geometry>
				<cylinder length="0.122" radius="0.60"/>
			</geometry>
		</visual>	
	</link>

  <link name="base_rot">
		<visual>
          	<geometry>
              <box size="0.015 0.015 0.036" />
			      </geometry>
		</visual>	
	</link>
    
    <joint name="base_joint" type="revolute">
      <parent link="base_link"/>
      <child link="base_rot"/>
      <origin xyz="0 0 0.014" rpy="0 0 0" />
      <axis xyz="0 0 -1"/>
      <limit lower="-1.57" upper="1.57" />
    </joint>
    
    <link name="arm1">
		<visual>
          <origin xyz="0.0075 0.0075 0.30" rpy="0 0 0" />
          	<geometry>
              <box size="0.015 0.015 0.60"/>
            </geometry>
		</visual>	  
     
	</link>
    <joint name="shoulder_joint" type="revolute">
      <parent link="base_rot"/>
      <child link="arm1"/>
      <origin xyz="0 0 0.318" rpy="0 0 0" />
      <axis xyz="1 0 0"/>
      <limit lower="-2.094" upper="-1.571" />
    </joint>
    
    <link name="arm2">
		<visual>
          <origin xyz="0.0075 0.0075 0.255" rpy="0 0 0" />
          	<geometry>
              <box size="0.015 0.015 0.51"/>
            </geometry>
		</visual>	
	  </link>
    
    <joint name="elbow_joint" type="revolute">
      <parent link="arm1"/>
      <child link="arm2"/>
      <origin xyz="0 0 0.238" rpy="0 0 0" />
      <axis xyz="1 0 0"/>
        <limit lower="-1.92" upper="1.92" />
    </joint>
</robot>  


    
